Workbook
Name CrewGuestSvcPerc: '[2]Operations Review'!$G$117:$H$117
Name Date: '[2]Operations Review'!$C$2
Name EffMerchPerc: '[2]Operations Review'!$G$121:$H$121
Name FoodSafetyPerc: '[2]Operations Review'!$G$115:$H$115
Name IHRPercPerNum: 20
Name Location: '[2]Operations Review'!$C$1
Name PCNum: '[2]Operations Review'!$C$4
Name ProdQualPerc: '[2]Operations Review'!$G$120:$H$120
Name PtsAvail: '[2]Operations Review'!$D$123
Name PtsAward: '[2]Operations Review'!$E$123:$F$123
Name RstCleanPerc: '[2]Operations Review'!$G$116:$H$116
Name StoreExpPerc: '[2]Operations Review'!$G$118:$H$118
Name Time: '[2]Operations Review'!$C$3
Name TotalPerc: '[2]Operations Review'!$G$123:$H$123

Sheet  Revisión de operaciones
A1: Ubicación
A2: Fecha del formulario
A3: Tiempo
A4: Persona responsable
A5: Evaluador
A8: Puntos posibles: | C8: =D123 -> 8 | D8: Agujas: | E8: =E123:F123 -> 0 | F8: Porcentaje: | H8: =G123 -> 0 | J8: Comentarios
A10: Riesgos inminentes para la salud | B10: RSI 1 | C10: Hay agua corriente caliente y fría disponible. | H10: Sí | I10: =IF(H10="Yes",20,IF(H10="No",0,IF(H10="Cured in the moment",20,"")))
B11: RSI 2 | C11: Gerente y miembros de la tripulación libres de enfermedades y síntomas. | H11: Sí | I11: =IF(H11="Yes",20,IF(H11="No",0,IF(H11="Cured in the moment",20,"")))
B12: RSI 3 | C12: Libre de productos adulterados/contaminados | H12: Sí | I12: =IF(H12="Yes",20,IF(H12="No",0,IF(H12="Cured in the moment",20,"")))
B13: RSI 4 | C13: Libre de atascos de alcantarillado | H13: Sí | I13: =IF(H13="Yes",20,IF(H13="No",0,IF(H13="Cured in the moment",20,"")))
B14: RSI 5 | C14: Libre de plagas que provoquen contaminación de superficies de contacto o alimentos. | H14: Sí | I14: =IF(H14="Yes",20,IF(H14="No",0,IF(H14="Cured in the moment",20,"")))
B15: RSI 6 | C15: El restaurante tiene desinfectante | H15: Sí | I15: =IF(H15="Yes",20,IF(H15="No",0,IF(H15="Cured in the moment",20,"")))
B16: RSI 7 | C16: Libre de inundaciones | H16: Sí | I16: =IF(H16="Yes",20,IF(H16="No",0,IF(H16="Cured in the moment",20,"")))
B17: RSI 8 | C17: Los alimentos controlados por tiempo y temperatura para seguridad (TCS) se mantienen a la temperatura adecuada y se documentan cada cuatro horas. | H17: Sí | I17: =IF(H17="Yes",20,IF(H17="No",0,IF(H17="Cured in the moment",20,"")))
B18: RSI 9 | C18: Se proporcionan lavabos para lavarse las manos. | H18: Sí | I18: =IF(H18="Yes",20,IF(H18="No",0,IF(H18="Cured in the moment",20,"")))
A20: Seguridad alimentaria - Sistema de saneamiento | B20: FS-SS 1 | C20: Las soluciones desinfectantes están limpias, tienen la concentración adecuada y hay tiras de prueba disponibles. | H20: Sí | I20: =IF(H20="Yes",2,IF(H20="No",0,IF(H20="N/A",2,"")))
B21: FS-SS 2 | C21: El fregadero de dos o tres compartimentos está instalado y se utiliza correctamente | H21: No | I21: =IF(H21="Yes",2,IF(H21="No",0,IF(H21="N/A",2,""))) -> 0
B22: FS-SS 3 | C22: Las superficies de los equipos y utensilios se lavan, enjuagan, desinfectan y secan al aire adecuadamente. | H22: Sí | I22: =IF(H22="Yes",2,IF(H22="No",0,IF(H22="N/A",2,"")))
B23: FS-SS 4 | C23: Se utilizan productos químicos aprobados, etiquetados y almacenados adecuadamente. | H23: No | I23: =IF(H23="Yes",2,IF(H23="No",0,IF(H23="N/A",2,""))) -> 0
B24: FS-SS 5 | C24: Las instalaciones en la parte trasera de la casa están limpias y mantenidas. | H24: Sí | I24: =IF(H24="Yes",2,IF(H24="No",0,IF(H24="N/A",2,"")))
A26: Seguridad alimentaria - Sistema de prácticas e higiene de los empleados | B26: FS-EH1 | C26: El gerente y los miembros de la tripulación comprenden el estándar de Dunkin' Brands para la salud de los empleados | H26: Sí | I26: =IF(H26="Yes",2,IF(H26="No",0,IF(H26="N/A",2,"")))
B27: FS-EH2 | C27: Hay instalaciones para lavarse las manos y se siguen prácticas de higiene. | H27: Sí | I27: =IF(H27="Yes",2,IF(H27="No",0,IF(H27="N/A",2,"")))
B28: FS-EH3 | C28: No hay contacto de las manos desnudas con alimentos listos para comer y hay guantes/barreras de un solo uso disponibles. | H28: Sí | I28: =IF(H28="Yes",2,IF(H28="No",0,IF(H28="N/A",2,"")))
A30: Seguridad alimentaria: sistema de control de tiempo y temperatura | B30: FS-TT1 | C30: El termómetro termopar con sonda para alimentos aprobado está en uso, es preciso y está desinfectado adecuadamente. | H30: Sí | I30: =IF(H30="Yes",2,IF(H30="No",0,IF(H30="N/A",2,"")))
B31: FS-TT2 | C31: Los alimentos refrigerados se mantienen a una temperatura de (35˚F a <41˚F) / (>2˚C a <5˚C) | H31: N / A | I31: =IF(H31="Yes",2,IF(H31="No",0,IF(H31="N/A",2,"")))
A33: Seguridad alimentaria - Sistema de buenas prácticas de venta minorista | B33: FS-GRP-1 | C33: Los alimentos y sus envases están protegidos de la contaminación y del contacto cruzado con alérgenos. | H33: Sí | I33: =IF(H33="Yes",2,IF(H33="No",0,IF(H33="N/A",2,"")))
B34: FS-GRP2 | C34: Todos los envases de alimentos se utilizan de forma adecuada. | H34: Sí | I34: =IF(H34="Yes",2,IF(H34="No",0,IF(H34="N/A",2,"")))
B35: FS-GRP3 | C35: Todos los productos alimenticios están aprobados y provienen de una fuente aprobada. | H35: Sí | I35: =IF(H35="Yes",2,IF(H35="No",0,IF(H35="N/A",2,"")))
B36: FS-GRP 4 | C36: Todos los alimentos están dentro del código de fecha y etiquetados adecuadamente. | H36: N / A | I36: =IF(H36="Yes",2,IF(H36="No",0,IF(H36="N/A",2,"")))
B37: FS-GRP 7 | C37: Restaurante libre de plagas y evidencia de plagas. | H37: Sí | I37: =IF(H37="Yes",2,IF(H37="No",0,IF(H37="N/A",2,"")))
B38: FS-GRP8 | C38: Los dispositivos de control de plagas se utilizan correctamente y solo los aplica un operador de control de plagas autorizado. | H38: Sí | I38: =IF(H38="Yes",2,IF(H38="No",0,IF(H38="N/A",2,"")))
A40: Seguridad alimentaria - Sistema de documentación | B40: FS-DS 1 | C40: La sección de Seguridad Alimentaria de los ROR está completa, es precisa y incluye acciones correctivas. | H40: No | I40: =IF(H40="Yes",2,IF(H40="No",0,IF(H40="N/A",2,""))) -> 0
B41: FS-DS 2 | C41: Los documentos de temperatura de mantenimiento en frío están completos, son precisos y incluyen acciones correctivas. | H41: Sí | I41: =IF(H41="Yes",2,IF(H41="No",0,IF(H41="N/A",2,"")))
B42: FS-DS 3 | C42: Los documentos recibidos están completos, precisos y con acciones correctivas. | H42: Sí | I42: =IF(H42="Yes",2,IF(H42="No",0,IF(H42="N/A",2,"")))
B43: FS-DS 4 | C43: Existe prueba de la documentación y los recursos de seguridad alimentaria requeridos (es decir, capacitación en comunicación de riesgos y MSDS/SDS, certificaciones de seguridad alimentaria, etc., (según lo exija la ley local) | H43: Sí | I43: =IF(H43="Yes",2,IF(H43="No",0,IF(H43="N/A",2,"")))
A45: Limpieza del restaurante | B45: RC1 | C45: ¿Está limpio y en buen estado el exterior? Evalúe la limpieza y el estado de la entrada, las puertas, las ventanas, la señalización y la iluminación a través de los ojos del huésped. | H45: Sí | I45: =IF(H45="Yes",2,IF(H45="No",0,IF(H45="N/A",2,"")))
B46: RC2 | C46: ¿El área del comedor está limpia, mantenida y el ambiente cumple con los requisitos de BR? | H46: Sí | I46: =IF(H46="Yes",2,IF(H46="No",0,IF(H46="N/A",2,"")))
B47: RC3 | C47: ¿El área de servicio y todas las áreas de la barra trasera están limpias, en buenas condiciones, cumpliendo con los requisitos de BR y se mantienen adecuadamente? | H47: Sí | I47: =IF(H47="Yes",2,IF(H47="No",0,IF(H47="N/A",2,"")))
B48: RC4 | C48: ¿Las básculas, los dispensadores y el abrelatas están limpios, en buenas condiciones y cumplen con los requisitos de BR? | H48: Sí | I48: =IF(H48="Yes",2,IF(H48="No",0,IF(H48="N/A",2,"")))
B49: RC5 | C49: ¿Los utensilios y recipientes para alimentos están limpios, en buenas condiciones y cumplen con los requisitos de BR? | H49: Sí | I49: =IF(H49="Yes",2,IF(H49="No",0,IF(H49="N/A",2,"")))
...

Sheet  Tanteo
A1: Conde de los Núms. | B1: Porcentaje
A2: 0 | B2: 100
A3: 1 | B3: 80
A4: 2 | B4: 60
A5: 3 | B5: 40
A6: 4 | B6: 20
A7: 5 | B7: 0

Sheet EOR PV PV 180
B1: Evaluación de seguridad alimentaria One Inspire
B3: Nombre y ubicación de la tienda: | C3: PV 180 CIUDADELA COMERCIAL UNICENTRO LOCAL 2 -158
B4: Nombre de la persona que completa el formulario | C4: CAROLINA MENDEZ - CAROLINA ZAMORA | G4: Riesgos inminentes para la salud | H4: =IF(COUNTIF(BB6,"0")>0,"PASA","NO PASA") -> PASA | BA4: Sí | BB4: =COUNTIF(E17:F23,BA4) -> 0 | BC4: 0 RSI
B5: Fecha | C5: 46272 | G5: Categoría | H5: Puntos disponibles | I5: Puntos otorgados | J5: Porcentaje
G6: Limpieza y Saneamiento | H6: 31 | I6: =SUM(F25:F31) -> 31 | J6: =I6/H6 -> 1 | BA6: No | BB6: =COUNTIF(E17:F23,BA6) -> 0 | BC6: RSI
B7: Puntuación: Valores en puntos | C7: 1. Cada pregunta vale 1, 5 o 7 puntos (los puntos son todo o nada) para un total de 117 puntos posibles. | G7: Salud e higiene de los empleados | H7: 18 | I7: =SUM(F32:F35) -> 18 | J7: =I7/H7 -> 1 | BA7: Curado en el momento | BB7: =COUNTIF(E17:F23,BA7) -> 0 | BC7: RSI CIM
C8: 2. Riesgo inminente para la salud (IHR): No hay valores asignados a las 7 preguntas; marque dentro de la pregunta crítica sistémica apropiada, escale el problema según sea necesario y aplique acciones correctivas inmediatas. Si hay un riesgo inminente para la salud (IHR) en el momento de la evaluación, entonces la pregunta crítica correspondiente dentro de la evaluación debe marcarse con un "No", independientemente de si el IHR se cura en el momento. Si hay un IHR, la revisión continuará y se completará en su totalidad para ayudar a descubrir la causa raíz del IHR. | G8: Hora y temperatura | H8: 31 | I8: =SUM(F36:F40) -> 31 | J8: =I8/H8 -> 1
G9: Buenas prácticas de venta minorista | H9: 19 | I9: =SUM(F41:F45) -> 19 | J9: =I9/H9 -> 1
G10: Manejo de plagas | H10: 13 | I10: =SUM(F46:F48) -> 13 | J10: =I10/H10 -> 1
B11: Calificaciones de riesgo | C11: Actividades de seguimiento | G11: Documentación | H11: 5 | I11: =SUM(F49:F53) -> 5 | J11: =I11/H11 -> 1
B12: Riesgo bajo 90% o más | C12: El restaurante cumple con la mayoría de los estándares de seguridad alimentaria. Las acciones correctivas para todos los hallazgos deben tomarse dentro de los 5 días posteriores a la recepción del informe de evaluación final. Realice un seguimiento con el equipo del restaurante para asegurarse de que se corrijan las oportunidades, se capacite a los miembros del equipo, etc. | G12: Total | H12: =SUM(H6:H11) -> 117 | I12: =SUM(I6:I11) -> 117 | J12: =I12/H12 -> 1
B13: Riesgo moderado 71% – 89% | C13: El restaurante cumple con algunas normas de seguridad alimentaria. Las medidas correctivas para todos los hallazgos deben tomarse dentro de los 5 días posteriores a la recepción del informe de evaluación final. Es posible que sea necesario realizar una documentación de seguimiento o una nueva visita para cualquier problema que no se haya corregido en el momento.
B14: Riesgo alto 70% o menos | C14: El restaurante no cumple con los estándares de seguridad alimentaria. Las acciones correctivas para todos los hallazgos deben tomarse dentro de los 5 días posteriores a la recepción del informe de evaluación final. Se debe realizar una nueva evaluación dentro de los 30 a 45 días para verificar que se corrijan las oportunidades y se eliminen las causas fundamentales. | G14: Puntuación FSA % y resultado de riesgo | I14: =J12 -> 1
B16: Riesgos inminentes para la salud | E16: Respuesta | G16: Comentarios
B17: Riesgos inminentes para la salud | C17: 1 | D17: IHR.1 Hay agua corriente caliente y fría disponible NOTA: Citar bajo pregunta GRP.3 | E17: Yes | AY17: =E17 -> Yes | BA17: Sí | BB17: =COUNTIF(AY17:AY23,BA17) -> 0 | BC17: 0 RSI
C18: 2 | D18: RSI.2 El gerente y los miembros del equipo están libres de enfermedades y síntomas NOTA: Citar bajo la pregunta GRP.3 | E18: Yes | AY18: =E18 -> Yes | BA18: No | BB18: =COUNTIF(AY17:AY23,BA18) -> 0 | BC18: RSI
C19: 3 | D19: RSI.3 Libre de productos adulterados/contaminados NOTA: Citar bajo pregunta GRP.3 | E19: Yes | AY19: =E19 -> Yes | BA19: Curado en el momento | BB19: =COUNTIF(AY17:AY23,BA19) -> 0 | BC19: RSI CIM
C20: 4 | D20: IHR.4 Libre de inundaciones/respaldo de alcantarillado NOTA: Citar bajo pregunta GRP.3 | E20: Yes | AY20: =E20 -> Yes
C21: 5 | D21: IHR.5 Libre de infestaciones de plagas que provoquen contaminación de alimentos y superficies en contacto. NOTA: Citar bajo la pregunta PM.1 | E21: Yes
C22: 6 | D22: IHR.6 Restaurante cuenta con sanitizante NOTA: Citar bajo pregunta GRP.3 | E22: Yes | AY22: =E22 -> Yes
C23: 7 | D23: IHR.7 Se proporcionan lavabos para lavarse las manos NOTA: Citar bajo pregunta GRP.3 | E23: Yes | AY23: =E23 -> Yes
B24: Sistemas de seguridad alimentaria en el comercio minorista | E24: Respuesta | F24: Agujas
B25: Limpieza y Saneamiento | C25: 1 | D25: CS.1 (Mayor) El agua caliente alcanza un mínimo de 85 °F (29 °C) en todos los lavamanos, 110 °F (43 °C) en los lavaplatos y 160 °F (71 °C) de temperatura superficial en todas las máquinas lavaplatos de alta temperatura. | E25: Yes | F25: =IF(E25="Yes",5,0) -> 5
C26: 2 | D26: CS.2 (Principal) El desinfectante se encuentra en la concentración adecuada en todos los lavabos, baldes, tazas y lavadoras de vajilla a baja temperatura. | E26: Yes | F26: =IF(E26="Yes",5,0) -> 5
C27: 3 | D27: CS.3 (Principal) Todos los productos químicos están aprobados, etiquetados adecuadamente y almacenados correctamente. | E27: Yes | F27: =IF(E27="Yes",5,0) -> 5
C28: 4 | D28: CS.4 (Menor) Locales exteriores e interiores (parte trasera de la casa) Las superficies que no entran en contacto con alimentos están limpias y se mantienen | E28: Yes | F28: =IF(E28="Yes",1,0) -> 1
C29: 5 | D29: CS.5 (Menor) Todos los fregaderos y lavavajillas están instalados correctamente y se utilizan adecuadamente. | E29: Yes | F29: =IF(E29="Yes",1,0) -> 1
C30: 6 | D30: CS.6 (Crítico) Los equipos en uso y las mesas de preparación se limpian y desinfectan con la frecuencia adecuada y se mantienen | E30: Yes | F30: =IF(E30="Yes",7,0) -> 7
C31: 7 | D31: CS.7 (Crítico) Los utensilios en uso y los artículos pequeños se limpian y desinfectan con la frecuencia adecuada y se mantienen | E31: Yes | F31: =IF(E31="Yes",7,0) -> 7
B32: Salud e higiene de los empleados | C32: 1 | D32: EH.1 (Menor) La persona a cargo comprende los estándares de marca para enfermedades y síntomas notificables y los miembros del equipo saben qué informar. | E32: Yes | F32: =IF(E32="Yes",1,0) -> 1
C33: 2 | D33: EH.2 (Mayor) Los lavabos para lavarse las manos están completamente abastecidos y los miembros del equipo se lavan las manos correctamente. | E33: Yes | F33: =IF(E33="Yes",5,0) -> 5
C34: 3 | D34: EH.3 (Mayor) Los miembros del equipo están siguiendo prácticas de higiene. | E34: Yes | F34: =IF(E34="Yes",5,0) -> 5
C35: 4 | D35: EH.4 (Crítico) Los miembros del equipo usan guantes correctamente y evitan el contacto con las manos desnudas. | E35: Yes | F35: =IF(E35="Yes",7,0) -> 7
B36: Hora y temperatura | C36: 1 | D36: TT.1 (Crítico) Alimentos refrigerados mantenidos a 41 °F (5°C) o menos | E36: Yes | F36: =IF(E36="Yes",7,0) -> 7
C37: 2 | D37: TT.2 (Principal) Control de tiempo y temperatura para seguridad (TCS) Los alimentos se manipulan adecuadamente | E37: Yes | F37: =IF(E37="Yes",5,0) -> 5
C38: 3 | D38: TT.3 (Crítico) Los alimentos se cocinan a la temperatura correcta.NOTA: Si la comida no se cocina en este lugar, marque con un círculo los puntos obtenidos como 7 | E38: Yes | F38: =IF(OR(E38="Yes",E38="NA"),7,0) -> 7
C39: 4 | D39: TT.4 (Crítico) Control de tiempo/temperatura para seguridad (TCS) Los alimentos en almacenamiento en caliente se mantienen a ≥ 135 °F (65°C) NOTA: Si no se mantiene caliente en esta ubicación, marque con un círculo los puntos obtenidos como 7 | E39: NA | F39: =IF(OR(E39="Yes",E39="NA"),7,0) -> 7
C40: 5 | D40: TT.5 (Principal) Los termómetros están calibrados adecuadamente y en uso. | E40: Yes | F40: =IF(E40="Yes",5,0) -> 5
B41: Buenas prácticas de venta minorista | C41: 1 | D41: GRP.1 (Mayor) Los alimentos y envases se almacenan de manera que estén protegidos y se cumplen todos los requisitos de gestión de alérgenos. | E41: Yes | F41: =IF(E41="Yes",5,0) -> 5
C42: 2 | D42: GRP.2 (Mayor) Las superficies en contacto con alimentos están protegidas de la contaminación y se manipulan adecuadamente. | E42: Yes | F42: =IF(E42="Yes",5,0) -> 5
...

Sheet P.A. PV 180
B2: Una plantilla de plan de acción mensual de InspireUtilice los resultados de One Inspire para crear un plan de acción para cerrar las brechas con los estándares de la marca. Todo aquello que no haya obtenido una puntuación "sí" en One Inspire es una brecha. Utilice el formato de objetivo SMART (específico, medible, alcanzable, realista y oportuno).
B3: OBJETIVO 1
B4: META: PINTURA Y LIPMPIEZA
B5: Accion correctiva / Plan de accion | C5: Responsable | D5: Fecha de ejecucion prevista | E5: Comentarios | F5: Fecha de cierre real (¿Terminado?)
D6: Fecha | E6: Comentarios | F6: Fecha (¿Hecho?)
B18: OBJETIVO 2
B19: META:
B20: Accion correctiva / Plan de accion | C20: Responsable | D20: Fecha de ejecucion prevista | E20: Comentarios | F20: Fecha de cierre real (¿Terminado?)
D21: Fecha | E21: Comentarios | F21: Fecha (¿Hecho?)
B32: OBJETIVO 3
B33: META:
B34: Accion correctiva / Plan de accion | C34: Responsable | D34: Fecha de ejecucion prevista | E34: Comentarios | F34: Fecha de cierre real (¿Terminado?)
D35: Fecha | E35: Comentarios | F35: Fecha (¿Hecho?)

Sheet EOR PV 296
B1: Evaluación de seguridad alimentaria One Inspire
B3: Nombre y ubicación de la tienda: | C3: PV 296 EDIFICIO BAVARIA CALLE 127
B4: Nombre de la persona que completa el formulario | C4: CAROLINA MENDEZ - CAROLINA ZAMORA CASTILLO | G4: Riesgos inminentes para la salud | H4: =IF(COUNTIF(BB6,"0")>0,"PASA","NO PASA") -> PASA | BA4: Sí | BB4: =COUNTIF(E17:F23,BA4) -> 0 | BC4: 0 RSI
B5: Fecha | C5: 46272 | G5: Categoría | H5: Puntos disponibles | I5: Puntos otorgados | J5: Porcentaje
G6: Limpieza y Saneamiento | H6: 31 | I6: =SUM(F25:F31) -> 31 | J6: =I6/H6 -> 1 | BA6: No | BB6: =COUNTIF(E17:F23,BA6) -> 0 | BC6: RSI
B7: Puntuación: Valores en puntos | C7: 1. Cada pregunta vale 1, 5 o 7 puntos (los puntos son todo o nada) para un total de 117 puntos posibles. | G7: Salud e higiene de los empleados | H7: 18 | I7: =SUM(F32:F35) -> 18 | J7: =I7/H7 -> 1 | BA7: Curado en el momento | BB7: =COUNTIF(E17:F23,BA7) -> 0 | BC7: RSI CIM
C8: 2. Riesgo inminente para la salud (IHR): No hay valores asignados a las 7 preguntas; marque dentro de la pregunta crítica sistémica apropiada, escale el problema según sea necesario y aplique acciones correctivas inmediatas. Si hay un riesgo inminente para la salud (IHR) en el momento de la evaluación, entonces la pregunta crítica correspondiente dentro de la evaluación debe marcarse con un "No", independientemente de si el IHR se cura en el momento. Si hay un IHR, la revisión continuará y se completará en su totalidad para ayudar a descubrir la causa raíz del IHR. | G8: Hora y temperatura | H8: 31 | I8: =SUM(F36:F40) -> 31 | J8: =I8/H8 -> 1
G9: Buenas prácticas de venta minorista | H9: 19 | I9: =SUM(F41:F45) -> 19 | J9: =I9/H9 -> 1
G10: Manejo de plagas | H10: 13 | I10: =SUM(F46:F48) -> 13 | J10: =I10/H10 -> 1
B11: Calificaciones de riesgo | C11: Actividades de seguimiento | G11: Documentación | H11: 5 | I11: =SUM(F49:F53) -> 5 | J11: =I11/H11 -> 1
B12: Riesgo bajo 90% o más | C12: El restaurante cumple con la mayoría de los estándares de seguridad alimentaria. Las acciones correctivas para todos los hallazgos deben tomarse dentro de los 5 días posteriores a la recepción del informe de evaluación final. Realice un seguimiento con el equipo del restaurante para asegurarse de que se corrijan las oportunidades, se capacite a los miembros del equipo, etc. | G12: Total | H12: =SUM(H6:H11) -> 117 | I12: =SUM(I6:I11) -> 117 | J12: =I12/H12 -> 1
B13: Riesgo moderado 71% – 89% | C13: El restaurante cumple con algunas normas de seguridad alimentaria. Las medidas correctivas para todos los hallazgos deben tomarse dentro de los 5 días posteriores a la recepción del informe de evaluación final. Es posible que sea necesario realizar una documentación de seguimiento o una nueva visita para cualquier problema que no se haya corregido en el momento.
B14: Riesgo alto 70% o menos | C14: El restaurante no cumple con los estándares de seguridad alimentaria. Las acciones correctivas para todos los hallazgos deben tomarse dentro de los 5 días posteriores a la recepción del informe de evaluación final. Se debe realizar una nueva evaluación dentro de los 30 a 45 días para verificar que se corrijan las oportunidades y se eliminen las causas fundamentales. | G14: Puntuación FSA % y resultado de riesgo | I14: =J12 -> 1
B16: Riesgos inminentes para la salud | E16: Respuesta | G16: Comentarios
B17: Riesgos inminentes para la salud | C17: 1 | D17: IHR.1 Hay agua corriente caliente y fría disponible NOTA: Citar bajo pregunta GRP.3 | E17: Yes | AY17: =E17 -> Yes | BA17: Sí | BB17: =COUNTIF(AY17:AY23,BA17) -> 0 | BC17: 0 RSI
C18: 2 | D18: RSI.2 El gerente y los miembros del equipo están libres de enfermedades y síntomas NOTA: Citar bajo la pregunta GRP.3 | E18: Yes | AY18: =E18 -> Yes | BA18: No | BB18: =COUNTIF(AY17:AY23,BA18) -> 0 | BC18: RSI
C19: 3 | D19: RSI.3 Libre de productos adulterados/contaminados NOTA: Citar bajo pregunta GRP.3 | E19: Yes | AY19: =E19 -> Yes | BA19: Curado en el momento | BB19: =COUNTIF(AY17:AY23,BA19) -> 0 | BC19: RSI CIM
C20: 4 | D20: IHR.4 Libre de inundaciones/respaldo de alcantarillado NOTA: Citar bajo pregunta GRP.3 | E20: Yes | AY20: =E20 -> Yes
C21: 5 | D21: IHR.5 Libre de infestaciones de plagas que provoquen contaminación de alimentos y superficies en contacto. NOTA: Citar bajo la pregunta PM.1 | E21: Yes
C22: 6 | D22: IHR.6 Restaurante cuenta con sanitizante NOTA: Citar bajo pregunta GRP.3 | E22: Yes | AY22: =E22 -> Yes
C23: 7 | D23: IHR.7 Se proporcionan lavabos para lavarse las manos NOTA: Citar bajo pregunta GRP.3 | E23: Yes | AY23: =E23 -> Yes
B24: Sistemas de seguridad alimentaria en el comercio minorista | E24: Respuesta | F24: Agujas | G24: Comentarios
B25: Limpieza y Saneamiento | C25: 1 | D25: CS.1 (Mayor) El agua caliente alcanza un mínimo de 85 °F (29 °C) en todos los lavamanos, 110 °F (43 °C) en los lavaplatos y 160 °F (71 °C) de temperatura superficial en todas las máquinas lavaplatos de alta temperatura. | E25: Yes | F25: =IF(E25="Yes",5,0) -> 5
C26: 2 | D26: CS.2 (Principal) El desinfectante se encuentra en la concentración adecuada en todos los lavabos, baldes, tazas y lavadoras de vajilla a baja temperatura. | E26: Yes | F26: =IF(E26="Yes",5,0) -> 5
C27: 3 | D27: CS.3 (Principal) Todos los productos químicos están aprobados, etiquetados adecuadamente y almacenados correctamente. | E27: Yes | F27: =IF(E27="Yes",5,0) -> 5
C28: 4 | D28: CS.4 (Menor) Locales exteriores e interiores (parte trasera de la casa) Las superficies que no entran en contacto con alimentos están limpias y se mantienen | E28: Yes | F28: =IF(E28="Yes",1,0) -> 1
C29: 5 | D29: CS.5 (Menor) Todos los fregaderos y lavavajillas están instalados correctamente y se utilizan adecuadamente. | E29: Yes | F29: =IF(E29="Yes",1,0) -> 1
C30: 6 | D30: CS.6 (Crítico) Los equipos en uso y las mesas de preparación se limpian y desinfectan con la frecuencia adecuada y se mantienen | E30: Yes | F30: =IF(E30="Yes",7,0) -> 7
C31: 7 | D31: CS.7 (Crítico) Los utensilios en uso y los artículos pequeños se limpian y desinfectan con la frecuencia adecuada y se mantienen | E31: Yes | F31: =IF(E31="Yes",7,0) -> 7
B32: Salud e higiene de los empleados | C32: 1 | D32: EH.1 (Menor) La persona a cargo comprende los estándares de marca para enfermedades y síntomas notificables y los miembros del equipo saben qué informar. | E32: Yes | F32: =IF(E32="Yes",1,0) -> 1
C33: 2 | D33: EH.2 (Mayor) Los lavabos para lavarse las manos están completamente abastecidos y los miembros del equipo se lavan las manos correctamente. | E33: Yes | F33: =IF(E33="Yes",5,0) -> 5
C34: 3 | D34: EH.3 (Mayor) Los miembros del equipo están siguiendo prácticas de higiene. | E34: Yes | F34: =IF(E34="Yes",5,0) -> 5
C35: 4 | D35: EH.4 (Crítico) Los miembros del equipo usan guantes correctamente y evitan el contacto con las manos desnudas. | E35: Yes | F35: =IF(E35="Yes",7,0) -> 7
B36: Hora y temperatura | C36: 1 | D36: TT.1 (Crítico) Alimentos refrigerados mantenidos a 41 °F (5°C) o menos | E36: Yes | F36: =IF(E36="Yes",7,0) -> 7
C37: 2 | D37: TT.2 (Principal) Control de tiempo y temperatura para seguridad (TCS) Los alimentos se manipulan adecuadamente | E37: Yes | F37: =IF(E37="Yes",5,0) -> 5
C38: 3 | D38: TT.3 (Crítico) Los alimentos se cocinan a la temperatura correcta.NOTA: Si la comida no se cocina en este lugar, marque con un círculo los puntos obtenidos como 7 | E38: Yes | F38: =IF(OR(E38="Yes",E38="NA"),7,0) -> 7
C39: 4 | D39: TT.4 (Crítico) Control de tiempo/temperatura para seguridad (TCS) Los alimentos en almacenamiento en caliente se mantienen a ≥ 135 °F (65°C) NOTA: Si no se mantiene caliente en esta ubicación, marque con un círculo los puntos obtenidos como 7 | E39: Yes | F39: =IF(OR(E39="Yes",E39="NA"),7,0) -> 7
C40: 5 | D40: TT.5 (Principal) Los termómetros están calibrados adecuadamente y en uso. | E40: Yes | F40: =IF(E40="Yes",5,0) -> 5
B41: Buenas prácticas de venta minorista | C41: 1 | D41: GRP.1 (Mayor) Los alimentos y envases se almacenan de manera que estén protegidos y se cumplen todos los requisitos de gestión de alérgenos. | E41: Yes | F41: =IF(E41="Yes",5,0) -> 5
C42: 2 | D42: GRP.2 (Mayor) Las superficies en contacto con alimentos están protegidas de la contaminación y se manipulan adecuadamente. | E42: Yes | F42: =IF(E42="Yes",5,0) -> 5
...

Sheet P.A. PV 296
B2: Una plantilla de plan de acción mensual de InspireUtilice los resultados de One Inspire para crear un plan de acción para cerrar las brechas con los estándares de la marca. Todo aquello que no haya obtenido una puntuación "sí" en One Inspire es una brecha. Utilice el formato de objetivo SMART (específico, medible, alcanzable, realista y oportuno).
B3: OBJETIVO 1
B4: META:
B5: Accion correctiva / Plan de accion | C5: Responsable | D5: Fecha de ejecucion prevista | E5: Comentarios | F5: Fecha de cierre real (¿Terminado?)
D6: Fecha | E6: Comentarios | F6: Fecha (¿Hecho?)
B18: OBJETIVO 2
B19: META:
B20: Accion correctiva / Plan de accion | C20: MANTENIMIENTO | D20: Fecha de ejecucion prevista | E20: Comentarios | F20: Fecha de cierre real (¿Terminado?)
D21: Fecha | E21: Comentarios | F21: Fecha (¿Hecho?)
B32: OBJETIVO 3
B33: META:
B34: Accion correctiva / Plan de accion | C34: Responsable | D34: Fecha de ejecucion prevista | E34: Comentarios | F34: Fecha de cierre real (¿Terminado?)
D35: Fecha | E35: Comentarios | F35: Fecha (¿Hecho?)

Sheet EOR PV 106
B1: Evaluación de seguridad alimentaria One Inspire
B3: Nombre y ubicación de la tienda: | C3: PV 106 CALLE 140 # 12-51 BQ A
B4: Nombre de la persona que completa el formulario | C4: JENNIFER QUINTERO - CAROLINA ZAMORA | G4: Riesgos inminentes para la salud | H4: =IF(COUNTIF(BB6,"0")>0,"PASA","NO PASA") -> PASA | BA4: Sí | BB4: =COUNTIF(E17:F23,BA4) -> 0 | BC4: 0 RSI
B5: Fecha | C5: 46276 | G5: Categoría | H5: Puntos disponibles | I5: Puntos otorgados | J5: Porcentaje
G6: Limpieza y Saneamiento | H6: 31 | I6: =SUM(F25:F31) -> 31 | J6: =I6/H6 -> 1 | BA6: No | BB6: =COUNTIF(E17:F23,BA6) -> 0 | BC6: RSI
B7: Puntuación: Valores en puntos | C7: 1. Cada pregunta vale 1, 5 o 7 puntos (los puntos son todo o nada) para un total de 117 puntos posibles. | G7: Salud e higiene de los empleados | H7: 18 | I7: =SUM(F32:F35) -> 18 | J7: =I7/H7 -> 1 | BA7: Curado en el momento | BB7: =COUNTIF(E17:F23,BA7) -> 0 | BC7: RSI CIM
C8: 2. Riesgo inminente para la salud (IHR): No hay valores asignados a las 7 preguntas; marque dentro de la pregunta crítica sistémica apropiada, escale el problema según sea necesario y aplique acciones correctivas inmediatas. Si hay un riesgo inminente para la salud (IHR) en el momento de la evaluación, entonces la pregunta crítica correspondiente dentro de la evaluación debe marcarse con un "No", independientemente de si el IHR se cura en el momento. Si hay un IHR, la revisión continuará y se completará en su totalidad para ayudar a descubrir la causa raíz del IHR. | G8: Hora y temperatura | H8: 31 | I8: =SUM(F36:F40) -> 31 | J8: =I8/H8 -> 1
G9: Buenas prácticas de venta minorista | H9: 19 | I9: =SUM(F41:F45) -> 19 | J9: =I9/H9 -> 1
G10: Manejo de plagas | H10: 13 | I10: =SUM(F46:F48) -> 13 | J10: =I10/H10 -> 1
B11: Calificaciones de riesgo | C11: Actividades de seguimiento | G11: Documentación | H11: 5 | I11: =SUM(F49:F53) -> 5 | J11: =I11/H11 -> 1
B12: Riesgo bajo 90% o más | C12: El restaurante cumple con la mayoría de los estándares de seguridad alimentaria. Las acciones correctivas para todos los hallazgos deben tomarse dentro de los 5 días posteriores a la recepción del informe de evaluación final. Realice un seguimiento con el equipo del restaurante para asegurarse de que se corrijan las oportunidades, se capacite a los miembros del equipo, etc. | G12: Total | H12: =SUM(H6:H11) -> 117 | I12: =SUM(I6:I11) -> 117 | J12: =I12/H12 -> 1
B13: Riesgo moderado 71% – 89% | C13: El restaurante cumple con algunas normas de seguridad alimentaria. Las medidas correctivas para todos los hallazgos deben tomarse dentro de los 5 días posteriores a la recepción del informe de evaluación final. Es posible que sea necesario realizar una documentación de seguimiento o una nueva visita para cualquier problema que no se haya corregido en el momento.
B14: Riesgo alto 70% o menos | C14: El restaurante no cumple con los estándares de seguridad alimentaria. Las acciones correctivas para todos los hallazgos deben tomarse dentro de los 5 días posteriores a la recepción del informe de evaluación final. Se debe realizar una nueva evaluación dentro de los 30 a 45 días para verificar que se corrijan las oportunidades y se eliminen las causas fundamentales. | G14: Puntuación FSA % y resultado de riesgo | I14: =J12 -> 1
B16: Riesgos inminentes para la salud | E16: Respuesta | G16: Comentarios
B17: Riesgos inminentes para la salud | C17: 1 | D17: IHR.1 Hay agua corriente caliente y fría disponible NOTA: Citar bajo pregunta GRP.3 | E17: Yes | AY17: =E17 -> Yes | BA17: Sí | BB17: =COUNTIF(AY17:AY23,BA17) -> 0 | BC17: 0 RSI
C18: 2 | D18: RSI.2 El gerente y los miembros del equipo están libres de enfermedades y síntomas NOTA: Citar bajo la pregunta GRP.3 | E18: Yes | AY18: =E18 -> Yes | BA18: No | BB18: =COUNTIF(AY17:AY23,BA18) -> 0 | BC18: RSI
C19: 3 | D19: RSI.3 Libre de productos adulterados/contaminados NOTA: Citar bajo pregunta GRP.3 | E19: Yes | AY19: =E19 -> Yes | BA19: Curado en el momento | BB19: =COUNTIF(AY17:AY23,BA19) -> 0 | BC19: RSI CIM
C20: 4 | D20: IHR.4 Libre de inundaciones/respaldo de alcantarillado NOTA: Citar bajo pregunta GRP.3 | E20: Yes | AY20: =E20 -> Yes
C21: 5 | D21: IHR.5 Libre de infestaciones de plagas que provoquen contaminación de alimentos y superficies en contacto. NOTA: Citar bajo la pregunta PM.1 | E21: Yes
C22: 6 | D22: IHR.6 Restaurante cuenta con sanitizante NOTA: Citar bajo pregunta GRP.3 | E22: Yes | AY22: =E22 -> Yes
C23: 7 | D23: IHR.7 Se proporcionan lavabos para lavarse las manos NOTA: Citar bajo pregunta GRP.3 | E23: Yes | AY23: =E23 -> Yes
B24: Sistemas de seguridad alimentaria en el comercio minorista | E24: Respuesta | F24: Agujas | G24: Comentarios
B25: Limpieza y Saneamiento | C25: 1 | D25: CS.1 (Mayor) El agua caliente alcanza un mínimo de 85 °F (29 °C) en todos los lavamanos, 110 °F (43 °C) en los lavaplatos y 160 °F (71 °C) de temperatura superficial en todas las máquinas lavaplatos de alta temperatura. | E25: Yes | F25: =IF(E25="Yes",5,0) -> 5
C26: 2 | D26: CS.2 (Principal) El desinfectante se encuentra en la concentración adecuada en todos los lavabos, baldes, tazas y lavadoras de vajilla a baja temperatura. | E26: Yes | F26: =IF(E26="Yes",5,0) -> 5
C27: 3 | D27: CS.3 (Principal) Todos los productos químicos están aprobados, etiquetados adecuadamente y almacenados correctamente. | E27: Yes | F27: =IF(E27="Yes",5,0) -> 5
C28: 4 | D28: CS.4 (Menor) Locales exteriores e interiores (parte trasera de la casa) Las superficies que no entran en contacto con alimentos están limpias y se mantienen | E28: Yes | F28: =IF(E28="Yes",1,0) -> 1
C29: 5 | D29: CS.5 (Menor) Todos los fregaderos y lavavajillas están instalados correctamente y se utilizan adecuadamente. | E29: Yes | F29: =IF(E29="Yes",1,0) -> 1
C30: 6 | D30: CS.6 (Crítico) Los equipos en uso y las mesas de preparación se limpian y desinfectan con la frecuencia adecuada y se mantienen | E30: Yes | F30: =IF(E30="Yes",7,0) -> 7
C31: 7 | D31: CS.7 (Crítico) Los utensilios en uso y los artículos pequeños se limpian y desinfectan con la frecuencia adecuada y se mantienen | E31: Yes | F31: =IF(E31="Yes",7,0) -> 7
B32: Salud e higiene de los empleados | C32: 1 | D32: EH.1 (Menor) La persona a cargo comprende los estándares de marca para enfermedades y síntomas notificables y los miembros del equipo saben qué informar. | E32: Yes | F32: =IF(E32="Yes",1,0) -> 1
C33: 2 | D33: EH.2 (Mayor) Los lavabos para lavarse las manos están completamente abastecidos y los miembros del equipo se lavan las manos correctamente. | E33: Yes | F33: =IF(E33="Yes",5,0) -> 5
C34: 3 | D34: EH.3 (Mayor) Los miembros del equipo están siguiendo prácticas de higiene. | E34: Yes | F34: =IF(E34="Yes",5,0) -> 5
C35: 4 | D35: EH.4 (Crítico) Los miembros del equipo usan guantes correctamente y evitan el contacto con las manos desnudas. | E35: Yes | F35: =IF(E35="Yes",7,0) -> 7
B36: Hora y temperatura | C36: 1 | D36: TT.1 (Crítico) Alimentos refrigerados mantenidos a 41 °F (5°C) o menos | E36: Yes | F36: =IF(E36="Yes",7,0) -> 7
C37: 2 | D37: TT.2 (Principal) Control de tiempo y temperatura para seguridad (TCS) Los alimentos se manipulan adecuadamente | E37: Yes | F37: =IF(E37="Yes",5,0) -> 5
C38: 3 | D38: TT.3 (Crítico) Los alimentos se cocinan a la temperatura correcta.NOTA: Si la comida no se cocina en este lugar, marque con un círculo los puntos obtenidos como 7 | E38: Yes | F38: =IF(OR(E38="Yes",E38="NA"),7,0) -> 7
C39: 4 | D39: TT.4 (Crítico) Control de tiempo/temperatura para seguridad (TCS) Los alimentos en almacenamiento en caliente se mantienen a ≥ 135 °F (65°C) NOTA: Si no se mantiene caliente en esta ubicación, marque con un círculo los puntos obtenidos como 7 | E39: Yes | F39: =IF(OR(E39="Yes",E39="NA"),7,0) -> 7
C40: 5 | D40: TT.5 (Principal) Los termómetros están calibrados adecuadamente y en uso. | E40: Yes | F40: =IF(E40="Yes",5,0) -> 5
B41: Buenas prácticas de venta minorista | C41: 1 | D41: GRP.1 (Mayor) Los alimentos y envases se almacenan de manera que estén protegidos y se cumplen todos los requisitos de gestión de alérgenos. | E41: Yes | F41: =IF(E41="Yes",5,0) -> 5
C42: 2 | D42: GRP.2 (Mayor) Las superficies en contacto con alimentos están protegidas de la contaminación y se manipulan adecuadamente. | E42: Yes | F42: =IF(E42="Yes",5,0) -> 5
...

Sheet P.A. PV 106
B2: Una plantilla de plan de acción mensual de InspireUtilice los resultados de One Inspire para crear un plan de acción para cerrar las brechas con los estándares de la marca. Todo aquello que no haya obtenido una puntuación "sí" en One Inspire es una brecha. Utilice el formato de objetivo SMART (específico, medible, alcanzable, realista y oportuno).
B3: OBJETIVO 1
B4: META:
B5: Accion correctiva / Plan de accion | C5: Responsable | D5: Fecha de ejecucion prevista | E5: Comentarios | F5: Fecha de cierre real (¿Terminado?)
D6: Fecha | E6: Comentarios | F6: Fecha (¿Hecho?)
B7: Reforzar limpieza en rincones para evitar exceso de polvo | C7: JENNIFER QUINTERO | D7: INMEDIATO
B8: Soliictra fumigacion y mantenimiento para cerrar huecos que ayuden a la proiferacion de plagas | C8: JENNIFER QUINTERO | D8: 46295
B9: Realizar constante retroalimentacion sobre procesos de higiene y lavado de manos | C9: JENNIFER QUINTERO | D9: 46295
B18: OBJETIVO 2
B19: META:
B20: Accion correctiva / Plan de accion | C20: Responsable | D20: Fecha de ejecucion prevista | E20: Comentarios | F20: Fecha de cierre real (¿Terminado?)
D21: Fecha | E21: Comentarios | F21: Fecha (¿Hecho?)
B32: OBJETIVO 3
B33: META:
B34: Accion correctiva / Plan de accion | C34: Responsable | D34: Fecha de ejecucion prevista | E34: Comentarios | F34: Fecha de cierre real (¿Terminado?)
D35: Fecha | E35: Comentarios | F35: Fecha (¿Hecho?)

Sheet EOR PV295
B1: Evaluación de seguridad alimentaria One Inspire
B3: Nombre y ubicación de la tienda: | C3: PV 295 EDIFICIO SOKO CALLE 147 #19-45
B4: Nombre de la persona que completa el formulario | C4: JENNIFER QUINTERO - CAROLINA ZAMORA CASTILLO | G4: Riesgos inminentes para la salud | H4: =IF(COUNTIF(BB6,"0")>0,"PASA","NO PASA") -> PASA | BA4: Sí | BB4: =COUNTIF(E17:F23,BA4) -> 0 | BC4: 0 RSI
B5: Fecha | C5: 46276 | G5: Categoría | H5: Puntos disponibles | I5: Puntos otorgados | J5: Porcentaje
G6: Limpieza y Saneamiento | H6: 31 | I6: =SUM(F25:F31) -> 31 | J6: =I6/H6 -> 1 | BA6: No | BB6: =COUNTIF(E17:F23,BA6) -> 0 | BC6: RSI
B7: Puntuación: Valores en puntos | C7: 1. Cada pregunta vale 1, 5 o 7 puntos (los puntos son todo o nada) para un total de 117 puntos posibles. | G7: Salud e higiene de los empleados | H7: 18 | I7: =SUM(F32:F35) -> 18 | J7: =I7/H7 -> 1 | BA7: Curado en el momento | BB7: =COUNTIF(E17:F23,BA7) -> 0 | BC7: RSI CIM
C8: 2. Riesgo inminente para la salud (IHR): No hay valores asignados a las 7 preguntas; marque dentro de la pregunta crítica sistémica apropiada, escale el problema según sea necesario y aplique acciones correctivas inmediatas. Si hay un riesgo inminente para la salud (IHR) en el momento de la evaluación, entonces la pregunta crítica correspondiente dentro de la evaluación debe marcarse con un "No", independientemente de si el IHR se cura en el momento. Si hay un IHR, la revisión continuará y se completará en su totalidad para ayudar a descubrir la causa raíz del IHR. | G8: Hora y temperatura | H8: 31 | I8: =SUM(F36:F40) -> 31 | J8: =I8/H8 -> 1
G9: Buenas prácticas de venta minorista | H9: 19 | I9: =SUM(F41:F45) -> 19 | J9: =I9/H9 -> 1
G10: Manejo de plagas | H10: 13 | I10: =SUM(F46:F48) -> 13 | J10: =I10/H10 -> 1
B11: Calificaciones de riesgo | C11: Actividades de seguimiento | G11: Documentación | H11: 5 | I11: =SUM(F49:F53) -> 5 | J11: =I11/H11 -> 1
B12: Riesgo bajo 90% o más | C12: El restaurante cumple con la mayoría de los estándares de seguridad alimentaria. Las acciones correctivas para todos los hallazgos deben tomarse dentro de los 5 días posteriores a la recepción del informe de evaluación final. Realice un seguimiento con el equipo del restaurante para asegurarse de que se corrijan las oportunidades, se capacite a los miembros del equipo, etc. | G12: Total | H12: =SUM(H6:H11) -> 117 | I12: =SUM(I6:I11) -> 117 | J12: =I12/H12 -> 1
B13: Riesgo moderado 71% – 89% | C13: El restaurante cumple con algunas normas de seguridad alimentaria. Las medidas correctivas para todos los hallazgos deben tomarse dentro de los 5 días posteriores a la recepción del informe de evaluación final. Es posible que sea necesario realizar una documentación de seguimiento o una nueva visita para cualquier problema que no se haya corregido en el momento.
B14: Riesgo alto 70% o menos | C14: El restaurante no cumple con los estándares de seguridad alimentaria. Las acciones correctivas para todos los hallazgos deben tomarse dentro de los 5 días posteriores a la recepción del informe de evaluación final. Se debe realizar una nueva evaluación dentro de los 30 a 45 días para verificar que se corrijan las oportunidades y se eliminen las causas fundamentales. | G14: Puntuación FSA % y resultado de riesgo | I14: =J12 -> 1
B16: Riesgos inminentes para la salud | E16: Respuesta | G16: Comentarios
B17: Riesgos inminentes para la salud | C17: 1 | D17: IHR.1 Hay agua corriente caliente y fría disponible NOTA: Citar bajo pregunta GRP.3 | E17: Yes | AY17: =E17 -> Yes | BA17: Sí | BB17: =COUNTIF(AY17:AY23,BA17) -> 0 | BC17: 0 RSI
C18: 2 | D18: RSI.2 El gerente y los miembros del equipo están libres de enfermedades y síntomas NOTA: Citar bajo la pregunta GRP.3 | E18: Yes | AY18: =E18 -> Yes | BA18: No | BB18: =COUNTIF(AY17:AY23,BA18) -> 0 | BC18: RSI
C19: 3 | D19: RSI.3 Libre de productos adulterados/contaminados NOTA: Citar bajo pregunta GRP.3 | E19: Yes | AY19: =E19 -> Yes | BA19: Curado en el momento | BB19: =COUNTIF(AY17:AY23,BA19) -> 0 | BC19: RSI CIM
C20: 4 | D20: IHR.4 Libre de inundaciones/respaldo de alcantarillado NOTA: Citar bajo pregunta GRP.3 | E20: Yes | AY20: =E20 -> Yes
C21: 5 | D21: IHR.5 Libre de infestaciones de plagas que provoquen contaminación de alimentos y superficies en contacto. NOTA: Citar bajo la pregunta PM.1 | E21: Yes
C22: 6 | D22: IHR.6 Restaurante cuenta con sanitizante NOTA: Citar bajo pregunta GRP.3 | E22: Yes | AY22: =E22 -> Yes
C23: 7 | D23: IHR.7 Se proporcionan lavabos para lavarse las manos NOTA: Citar bajo pregunta GRP.3 | E23: Yes | AY23: =E23 -> Yes
B24: Sistemas de seguridad alimentaria en el comercio minorista | E24: Respuesta | F24: Agujas | G24: Comentarios
B25: Limpieza y Saneamiento | C25: 1 | D25: CS.1 (Mayor) El agua caliente alcanza un mínimo de 85 °F (29 °C) en todos los lavamanos, 110 °F (43 °C) en los lavaplatos y 160 °F (71 °C) de temperatura superficial en todas las máquinas lavaplatos de alta temperatura. | E25: Yes | F25: =IF(E25="Yes",5,0) -> 5
C26: 2 | D26: CS.2 (Principal) El desinfectante se encuentra en la concentración adecuada en todos los lavabos, baldes, tazas y lavadoras de vajilla a baja temperatura. | E26: Yes | F26: =IF(E26="Yes",5,0) -> 5
C27: 3 | D27: CS.3 (Principal) Todos los productos químicos están aprobados, etiquetados adecuadamente y almacenados correctamente. | E27: Yes | F27: =IF(E27="Yes",5,0) -> 5
C28: 4 | D28: CS.4 (Menor) Locales exteriores e interiores (parte trasera de la casa) Las superficies que no entran en contacto con alimentos están limpias y se mantienen | E28: Yes | F28: =IF(E28="Yes",1,0) -> 1
C29: 5 | D29: CS.5 (Menor) Todos los fregaderos y lavavajillas están instalados correctamente y se utilizan adecuadamente. | E29: Yes | F29: =IF(E29="Yes",1,0) -> 1
C30: 6 | D30: CS.6 (Crítico) Los equipos en uso y las mesas de preparación se limpian y desinfectan con la frecuencia adecuada y se mantienen | E30: Yes | F30: =IF(E30="Yes",7,0) -> 7
C31: 7 | D31: CS.7 (Crítico) Los utensilios en uso y los artículos pequeños se limpian y desinfectan con la frecuencia adecuada y se mantienen | E31: Yes | F31: =IF(E31="Yes",7,0) -> 7
B32: Salud e higiene de los empleados | C32: 1 | D32: EH.1 (Menor) La persona a cargo comprende los estándares de marca para enfermedades y síntomas notificables y los miembros del equipo saben qué informar. | E32: Yes | F32: =IF(E32="Yes",1,0) -> 1
C33: 2 | D33: EH.2 (Mayor) Los lavabos para lavarse las manos están completamente abastecidos y los miembros del equipo se lavan las manos correctamente. | E33: Yes | F33: =IF(E33="Yes",5,0) -> 5
C34: 3 | D34: EH.3 (Mayor) Los miembros del equipo están siguiendo prácticas de higiene. | E34: Yes | F34: =IF(E34="Yes",5,0) -> 5
C35: 4 | D35: EH.4 (Crítico) Los miembros del equipo usan guantes correctamente y evitan el contacto con las manos desnudas. | E35: Yes | F35: =IF(E35="Yes",7,0) -> 7
B36: Hora y temperatura | C36: 1 | D36: TT.1 (Crítico) Alimentos refrigerados mantenidos a 41 °F (5°C) o menos | E36: Yes | F36: =IF(E36="Yes",7,0) -> 7
C37: 2 | D37: TT.2 (Principal) Control de tiempo y temperatura para seguridad (TCS) Los alimentos se manipulan adecuadamente | E37: Yes | F37: =IF(E37="Yes",5,0) -> 5
C38: 3 | D38: TT.3 (Crítico) Los alimentos se cocinan a la temperatura correcta.NOTA: Si la comida no se cocina en este lugar, marque con un círculo los puntos obtenidos como 7 | E38: Yes | F38: =IF(OR(E38="Yes",E38="NA"),7,0) -> 7
C39: 4 | D39: TT.4 (Crítico) Control de tiempo/temperatura para seguridad (TCS) Los alimentos en almacenamiento en caliente se mantienen a ≥ 135 °F (65°C) NOTA: Si no se mantiene caliente en esta ubicación, marque con un círculo los puntos obtenidos como 7 | E39: NA | F39: =IF(OR(E39="Yes",E39="NA"),7,0) -> 7
C40: 5 | D40: TT.5 (Principal) Los termómetros están calibrados adecuadamente y en uso. | E40: Yes | F40: =IF(E40="Yes",5,0) -> 5
B41: Buenas prácticas de venta minorista | C41: 1 | D41: GRP.1 (Mayor) Los alimentos y envases se almacenan de manera que estén protegidos y se cumplen todos los requisitos de gestión de alérgenos. | E41: Yes | F41: =IF(E41="Yes",5,0) -> 5
C42: 2 | D42: GRP.2 (Mayor) Las superficies en contacto con alimentos están protegidas de la contaminación y se manipulan adecuadamente. | E42: Yes | F42: =IF(E42="Yes",5,0) -> 5
...

Sheet P.A. PV295
B2: Una plantilla de plan de acción mensual de InspireUtilice los resultados de One Inspire para crear un plan de acción para cerrar las brechas con los estándares de la marca. Todo aquello que no haya obtenido una puntuación "sí" en One Inspire es una brecha. Utilice el formato de objetivo SMART (específico, medible, alcanzable, realista y oportuno).
B3: OBJETIVO 1
B4: META:
B5: Accion correctiva / Plan de accion | C5: Responsable | D5: Fecha de ejecucion prevista | E5: Comentarios | F5: Fecha de cierre real (¿Terminado?)
D6: Fecha | E6: Comentarios | F6: Fecha (¿Hecho?)
B18: OBJETIVO 2
B19: META:
B20: Accion correctiva / Plan de accion | C20: MANTENIMIENTO | D20: Fecha de ejecucion prevista | E20: Comentarios | F20: Fecha de cierre real (¿Terminado?)
D21: Fecha | E21: Comentarios | F21: Fecha (¿Hecho?)
B32: OBJETIVO 3
B33: META:
B34: Accion correctiva / Plan de accion | C34: Responsable | D34: Fecha de ejecucion prevista | E34: Comentarios | F34: Fecha de cierre real (¿Terminado?)
D35: Fecha | E35: Comentarios | F35: Fecha (¿Hecho?)

Sheet EOR PV 257
B1: Evaluación de seguridad alimentaria One Inspire
B3: Nombre y ubicación de la tienda: | C3: PV 257 ALCALA CALLE 134
B4: Nombre de la persona que completa el formulario | C4: EVERLEY GIL - CAROLINA ZAMORA | G4: Riesgos inminentes para la salud | H4: =IF(COUNTIF(BB6,"0")>0,"PASA","NO PASA") -> PASA | BA4: Sí | BB4: =COUNTIF(E17:F23,BA4) -> 0 | BC4: 0 RSI
B5: Fecha | C5: 46277 | G5: Categoría | H5: Puntos disponibles | I5: Puntos otorgados | J5: Porcentaje
G6: Limpieza y Saneamiento | H6: 31 | I6: =SUM(F25:F31) -> 31 | J6: =I6/H6 -> 1 | BA6: No | BB6: =COUNTIF(E17:F23,BA6) -> 0 | BC6: RSI
B7: Puntuación: Valores en puntos | C7: 1. Cada pregunta vale 1, 5 o 7 puntos (los puntos son todo o nada) para un total de 117 puntos posibles. | G7: Salud e higiene de los empleados | H7: 18 | I7: =SUM(F32:F35) -> 18 | J7: =I7/H7 -> 1 | BA7: Curado en el momento | BB7: =COUNTIF(E17:F23,BA7) -> 0 | BC7: RSI CIM
C8: 2. Riesgo inminente para la salud (IHR): No hay valores asignados a las 7 preguntas; marque dentro de la pregunta crítica sistémica apropiada, escale el problema según sea necesario y aplique acciones correctivas inmediatas. Si hay un riesgo inminente para la salud (IHR) en el momento de la evaluación, entonces la pregunta crítica correspondiente dentro de la evaluación debe marcarse con un "No", independientemente de si el IHR se cura en el momento. Si hay un IHR, la revisión continuará y se completará en su totalidad para ayudar a descubrir la causa raíz del IHR. | G8: Hora y temperatura | H8: 31 | I8: =SUM(F36:F40) -> 31 | J8: =I8/H8 -> 1
G9: Buenas prácticas de venta minorista | H9: 19 | I9: =SUM(F41:F45) -> 19 | J9: =I9/H9 -> 1
G10: Manejo de plagas | H10: 13 | I10: =SUM(F46:F48) -> 13 | J10: =I10/H10 -> 1
B11: Calificaciones de riesgo | C11: Actividades de seguimiento | G11: Documentación | H11: 5 | I11: =SUM(F49:F53) -> 5 | J11: =I11/H11 -> 1
B12: Riesgo bajo 90% o más | C12: El restaurante cumple con la mayoría de los estándares de seguridad alimentaria. Las acciones correctivas para todos los hallazgos deben tomarse dentro de los 5 días posteriores a la recepción del informe de evaluación final. Realice un seguimiento con el equipo del restaurante para asegurarse de que se corrijan las oportunidades, se capacite a los miembros del equipo, etc. | G12: Total | H12: =SUM(H6:H11) -> 117 | I12: =SUM(I6:I11) -> 117 | J12: =I12/H12 -> 1
B13: Riesgo moderado 71% – 89% | C13: El restaurante cumple con algunas normas de seguridad alimentaria. Las medidas correctivas para todos los hallazgos deben tomarse dentro de los 5 días posteriores a la recepción del informe de evaluación final. Es posible que sea necesario realizar una documentación de seguimiento o una nueva visita para cualquier problema que no se haya corregido en el momento.
B14: Riesgo alto 70% o menos | C14: El restaurante no cumple con los estándares de seguridad alimentaria. Las acciones correctivas para todos los hallazgos deben tomarse dentro de los 5 días posteriores a la recepción del informe de evaluación final. Se debe realizar una nueva evaluación dentro de los 30 a 45 días para verificar que se corrijan las oportunidades y se eliminen las causas fundamentales. | G14: Puntuación FSA % y resultado de riesgo | I14: =J12 -> 1
B16: Riesgos inminentes para la salud | E16: Respuesta | G16: Comentarios
B17: Riesgos inminentes para la salud | C17: 1 | D17: IHR.1 Hay agua corriente caliente y fría disponible NOTA: Citar bajo pregunta GRP.3 | E17: Yes | AY17: =E17 -> Yes | BA17: Sí | BB17: =COUNTIF(AY17:AY23,BA17) -> 0 | BC17: 0 RSI
C18: 2 | D18: RSI.2 El gerente y los miembros del equipo están libres de enfermedades y síntomas NOTA: Citar bajo la pregunta GRP.3 | E18: Yes | AY18: =E18 -> Yes | BA18: No | BB18: =COUNTIF(AY17:AY23,BA18) -> 0 | BC18: RSI
C19: 3 | D19: RSI.3 Libre de productos adulterados/contaminados NOTA: Citar bajo pregunta GRP.3 | E19: Yes | AY19: =E19 -> Yes | BA19: Curado en el momento | BB19: =COUNTIF(AY17:AY23,BA19) -> 0 | BC19: RSI CIM
C20: 4 | D20: IHR.4 Libre de inundaciones/respaldo de alcantarillado NOTA: Citar bajo pregunta GRP.3 | E20: Yes | AY20: =E20 -> Yes
C21: 5 | D21: IHR.5 Libre de infestaciones de plagas que provoquen contaminación de alimentos y superficies en contacto. NOTA: Citar bajo la pregunta PM.1 | E21: Yes
C22: 6 | D22: IHR.6 Restaurante cuenta con sanitizante NOTA: Citar bajo pregunta GRP.3 | E22: Yes | AY22: =E22 -> Yes
C23: 7 | D23: IHR.7 Se proporcionan lavabos para lavarse las manos NOTA: Citar bajo pregunta GRP.3 | E23: Yes | AY23: =E23 -> Yes
B24: Sistemas de seguridad alimentaria en el comercio minorista | E24: Respuesta | F24: Agujas | G24: Comentarios
B25: Limpieza y Saneamiento | C25: 1 | D25: CS.1 (Mayor) El agua caliente alcanza un mínimo de 85 °F (29 °C) en todos los lavamanos, 110 °F (43 °C) en los lavaplatos y 160 °F (71 °C) de temperatura superficial en todas las máquinas lavaplatos de alta temperatura. | E25: Yes | F25: =IF(E25="Yes",5,0) -> 5
C26: 2 | D26: CS.2 (Principal) El desinfectante se encuentra en la concentración adecuada en todos los lavabos, baldes, tazas y lavadoras de vajilla a baja temperatura. | E26: Yes | F26: =IF(E26="Yes",5,0) -> 5
C27: 3 | D27: CS.3 (Principal) Todos los productos químicos están aprobados, etiquetados adecuadamente y almacenados correctamente. | E27: Yes | F27: =IF(E27="Yes",5,0) -> 5
C28: 4 | D28: CS.4 (Menor) Locales exteriores e interiores (parte trasera de la casa) Las superficies que no entran en contacto con alimentos están limpias y se mantienen | E28: Yes | F28: =IF(E28="Yes",1,0) -> 1
C29: 5 | D29: CS.5 (Menor) Todos los fregaderos y lavavajillas están instalados correctamente y se utilizan adecuadamente. | E29: Yes | F29: =IF(E29="Yes",1,0) -> 1
C30: 6 | D30: CS.6 (Crítico) Los equipos en uso y las mesas de preparación se limpian y desinfectan con la frecuencia adecuada y se mantienen | E30: Yes | F30: =IF(E30="Yes",7,0) -> 7
C31: 7 | D31: CS.7 (Crítico) Los utensilios en uso y los artículos pequeños se limpian y desinfectan con la frecuencia adecuada y se mantienen | E31: Yes | F31: =IF(E31="Yes",7,0) -> 7
B32: Salud e higiene de los empleados | C32: 1 | D32: EH.1 (Menor) La persona a cargo comprende los estándares de marca para enfermedades y síntomas notificables y los miembros del equipo saben qué informar. | E32: Yes | F32: =IF(E32="Yes",1,0) -> 1
C33: 2 | D33: EH.2 (Mayor) Los lavabos para lavarse las manos están completamente abastecidos y los miembros del equipo se lavan las manos correctamente. | E33: Yes | F33: =IF(E33="Yes",5,0) -> 5
C34: 3 | D34: EH.3 (Mayor) Los miembros del equipo están siguiendo prácticas de higiene. | E34: Yes | F34: =IF(E34="Yes",5,0) -> 5
C35: 4 | D35: EH.4 (Crítico) Los miembros del equipo usan guantes correctamente y evitan el contacto con las manos desnudas. | E35: Yes | F35: =IF(E35="Yes",7,0) -> 7
B36: Hora y temperatura | C36: 1 | D36: TT.1 (Crítico) Alimentos refrigerados mantenidos a 41 °F (5°C) o menos | E36: Yes | F36: =IF(E36="Yes",7,0) -> 7
C37: 2 | D37: TT.2 (Principal) Control de tiempo y temperatura para seguridad (TCS) Los alimentos se manipulan adecuadamente | E37: Yes | F37: =IF(E37="Yes",5,0) -> 5
C38: 3 | D38: TT.3 (Crítico) Los alimentos se cocinan a la temperatura correcta.NOTA: Si la comida no se cocina en este lugar, marque con un círculo los puntos obtenidos como 7 | E38: NA | F38: =IF(OR(E38="Yes",E38="NA"),7,0) -> 7
C39: 4 | D39: TT.4 (Crítico) Control de tiempo/temperatura para seguridad (TCS) Los alimentos en almacenamiento en caliente se mantienen a ≥ 135 °F (65°C) NOTA: Si no se mantiene caliente en esta ubicación, marque con un círculo los puntos obtenidos como 7 | E39: NA | F39: =IF(OR(E39="Yes",E39="NA"),7,0) -> 7
C40: 5 | D40: TT.5 (Principal) Los termómetros están calibrados adecuadamente y en uso. | E40: Yes | F40: =IF(E40="Yes",5,0) -> 5
B41: Buenas prácticas de venta minorista | C41: 1 | D41: GRP.1 (Mayor) Los alimentos y envases se almacenan de manera que estén protegidos y se cumplen todos los requisitos de gestión de alérgenos. | E41: Yes | F41: =IF(E41="Yes",5,0) -> 5
C42: 2 | D42: GRP.2 (Mayor) Las superficies en contacto con alimentos están protegidas de la contaminación y se manipulan adecuadamente. | E42: Yes | F42: =IF(E42="Yes",5,0) -> 5
...

Sheet P.A. PV 257
B2: Una plantilla de plan de acción mensual de InspireUtilice los resultados de One Inspire para crear un plan de acción para cerrar las brechas con los estándares de la marca. Todo aquello que no haya obtenido una puntuación "sí" en One Inspire es una brecha. Utilice el formato de objetivo SMART (específico, medible, alcanzable, realista y oportuno).
B3: OBJETIVO 1
B4: META:
B5: Accion correctiva / Plan de accion | C5: Responsable | D5: Fecha de ejecucion prevista | E5: Comentarios | F5: Fecha de cierre real (¿Terminado?)
D6: Fecha | E6: Comentarios | F6: Fecha (¿Hecho?)
B18: OBJETIVO 2
B19: META:
B20: Accion correctiva / Plan de accion | C20: Responsable | D20: Fecha de ejecucion prevista | E20: Comentarios | F20: Fecha de cierre real (¿Terminado?)
D21: Fecha | E21: Comentarios | F21: Fecha (¿Hecho?)
B32: OBJETIVO 3
B33: META:
B34: Accion correctiva / Plan de accion | C34: Responsable | D34: Fecha de ejecucion prevista | E34: Comentarios | F34: Fecha de cierre real (¿Terminado?)
D35: Fecha | E35: Comentarios | F35: Fecha (¿Hecho?)

Sheet EOR PV 141
B1: Evaluación de seguridad alimentaria One Inspire
B3: Nombre y ubicación de la tienda: | C3: PV 141 AV. 13 No. 125-91- ESTACION TERPEL AUTOPISTA NORTE
B4: Nombre de la persona que completa el formulario | C4: EVERLEY GIL - CAROLINA ZAMORA | G4: Riesgos inminentes para la salud | H4: =IF(COUNTIF(BB6,"0")>0,"PASA","NO PASA") -> PASA | BA4: Sí | BB4: =COUNTIF(E17:F23,BA4) -> 0 | BC4: 0 RSI
B5: Fecha | C5: 46277 | G5: Categoría | H5: Puntos disponibles | I5: Puntos otorgados | J5: Porcentaje
G6: Limpieza y Saneamiento | H6: 31 | I6: =SUM(F25:F31) -> 31 | J6: =I6/H6 -> 1 | BA6: No | BB6: =COUNTIF(E17:F23,BA6) -> 0 | BC6: RSI
B7: Puntuación: Valores en puntos | C7: 1. Cada pregunta vale 1, 5 o 7 puntos (los puntos son todo o nada) para un total de 117 puntos posibles. | G7: Salud e higiene de los empleados | H7: 18 | I7: =SUM(F32:F35) -> 18 | J7: =I7/H7 -> 1 | BA7: Curado en el momento | BB7: =COUNTIF(E17:F23,BA7) -> 0 | BC7: RSI CIM
C8: 2. Riesgo inminente para la salud (IHR): No hay valores asignados a las 7 preguntas; marque dentro de la pregunta crítica sistémica apropiada, escale el problema según sea necesario y aplique acciones correctivas inmediatas. Si hay un riesgo inminente para la salud (IHR) en el momento de la evaluación, entonces la pregunta crítica correspondiente dentro de la evaluación debe marcarse con un "No", independientemente de si el IHR se cura en el momento. Si hay un IHR, la revisión continuará y se completará en su totalidad para ayudar a descubrir la causa raíz del IHR. | G8: Hora y temperatura | H8: 31 | I8: =SUM(F36:F40) -> 31 | J8: =I8/H8 -> 1
G9: Buenas prácticas de venta minorista | H9: 19 | I9: =SUM(F41:F45) -> 19 | J9: =I9/H9 -> 1
G10: Manejo de plagas | H10: 13 | I10: =SUM(F46:F48) -> 13 | J10: =I10/H10 -> 1
B11: Calificaciones de riesgo | C11: Actividades de seguimiento | G11: Documentación | H11: 5 | I11: =SUM(F49:F53) -> 5 | J11: =I11/H11 -> 1
B12: Riesgo bajo 90% o más | C12: El restaurante cumple con la mayoría de los estándares de seguridad alimentaria. Las acciones correctivas para todos los hallazgos deben tomarse dentro de los 5 días posteriores a la recepción del informe de evaluación final. Realice un seguimiento con el equipo del restaurante para asegurarse de que se corrijan las oportunidades, se capacite a los miembros del equipo, etc. | G12: Total | H12: =SUM(H6:H11) -> 117 | I12: =SUM(I6:I11) -> 117 | J12: =I12/H12 -> 1
B13: Riesgo moderado 71% – 89% | C13: El restaurante cumple con algunas normas de seguridad alimentaria. Las medidas correctivas para todos los hallazgos deben tomarse dentro de los 5 días posteriores a la recepción del informe de evaluación final. Es posible que sea necesario realizar una documentación de seguimiento o una nueva visita para cualquier problema que no se haya corregido en el momento.
B14: Riesgo alto 70% o menos | C14: El restaurante no cumple con los estándares de seguridad alimentaria. Las acciones correctivas para todos los hallazgos deben tomarse dentro de los 5 días posteriores a la recepción del informe de evaluación final. Se debe realizar una nueva evaluación dentro de los 30 a 45 días para verificar que se corrijan las oportunidades y se eliminen las causas fundamentales. | G14: Puntuación FSA % y resultado de riesgo | I14: =J12 -> 1
B16: Riesgos inminentes para la salud | E16: Respuesta | G16: Comentarios
B17: Riesgos inminentes para la salud | C17: 1 | D17: IHR.1 Hay agua corriente caliente y fría disponible NOTA: Citar bajo pregunta GRP.3 | E17: Yes | AY17: =E17 -> Yes | BA17: Sí | BB17: =COUNTIF(AY17:AY23,BA17) -> 0 | BC17: 0 RSI
C18: 2 | D18: RSI.2 El gerente y los miembros del equipo están libres de enfermedades y síntomas NOTA: Citar bajo la pregunta GRP.3 | E18: Yes | AY18: =E18 -> Yes | BA18: No | BB18: =COUNTIF(AY17:AY23,BA18) -> 0 | BC18: RSI
C19: 3 | D19: RSI.3 Libre de productos adulterados/contaminados NOTA: Citar bajo pregunta GRP.3 | E19: Yes | AY19: =E19 -> Yes | BA19: Curado en el momento | BB19: =COUNTIF(AY17:AY23,BA19) -> 0 | BC19: RSI CIM
C20: 4 | D20: IHR.4 Libre de inundaciones/respaldo de alcantarillado NOTA: Citar bajo pregunta GRP.3 | E20: Yes | AY20: =E20 -> Yes
C21: 5 | D21: IHR.5 Libre de infestaciones de plagas que provoquen contaminación de alimentos y superficies en contacto. NOTA: Citar bajo la pregunta PM.1 | E21: Yes
C22: 6 | D22: IHR.6 Restaurante cuenta con sanitizante NOTA: Citar bajo pregunta GRP.3 | E22: Yes | AY22: =E22 -> Yes
C23: 7 | D23: IHR.7 Se proporcionan lavabos para lavarse las manos NOTA: Citar bajo pregunta GRP.3 | E23: Yes | AY23: =E23 -> Yes
B24: Sistemas de seguridad alimentaria en el comercio minorista | E24: Respuesta | F24: Agujas
B25: Limpieza y Saneamiento | C25: 1 | D25: CS.1 (Mayor) El agua caliente alcanza un mínimo de 85 °F (29 °C) en todos los lavamanos, 110 °F (43 °C) en los lavaplatos y 160 °F (71 °C) de temperatura superficial en todas las máquinas lavaplatos de alta temperatura. | E25: Yes | F25: =IF(E25="Yes",5,0) -> 5
